<?xml version="1.0" ?>
<!-- =================================================================================== -->
<!-- |    This document was autogenerated by xacro from URDF.xacro                     | -->
<!-- |    EDITING THIS FILE BY HAND IS NOT RECOMMENDED                                 | -->
<!-- =================================================================================== -->
<robot name="URDF">
  <material name="silver">
    <color rgba="0.700 0.700 0.700 1.000"/>
  </material>
  <transmission name="Revolute1_tran">
    <type>transmission_interface/SimpleTransmission</type>
    <joint name="Revolute1">
      <hardwareInterface>hardware_interface/EffortJointInterface</hardwareInterface>
    </joint>
    <actuator name="Revolute1_actr">
      <hardwareInterface>hardware_interface/EffortJointInterface</hardwareInterface>
      <mechanicalReduction>1</mechanicalReduction>
    </actuator>
  </transmission>
  <transmission name="Revolute2_tran">
    <type>transmission_interface/SimpleTransmission</type>
    <joint name="Revolute2">
      <hardwareInterface>hardware_interface/EffortJointInterface</hardwareInterface>
    </joint>
    <actuator name="Revolute2_actr">
      <hardwareInterface>hardware_interface/EffortJointInterface</hardwareInterface>
      <mechanicalReduction>1</mechanicalReduction>
    </actuator>
  </transmission>
  <transmission name="Revolute3_tran">
    <type>transmission_interface/SimpleTransmission</type>
    <joint name="Revolute3">
      <hardwareInterface>hardware_interface/EffortJointInterface</hardwareInterface>
    </joint>
    <actuator name="Revolute3_actr">
      <hardwareInterface>hardware_interface/EffortJointInterface</hardwareInterface>
      <mechanicalReduction>1</mechanicalReduction>
    </actuator>
  </transmission>
  <transmission name="Revolute4_tran">
    <type>transmission_interface/SimpleTransmission</type>
    <joint name="Revolute4">
      <hardwareInterface>hardware_interface/EffortJointInterface</hardwareInterface>
    </joint>
    <actuator name="Revolute4_actr">
      <hardwareInterface>hardware_interface/EffortJointInterface</hardwareInterface>
      <mechanicalReduction>1</mechanicalReduction>
    </actuator>
  </transmission>
  <transmission name="Slider5_tran">
    <type>transmission_interface/SimpleTransmission</type>
    <joint name="Slider5">
      <hardwareInterface>hardware_interface/EffortJointInterface</hardwareInterface>
    </joint>
    <actuator name="Slider5_actr">
      <hardwareInterface>hardware_interface/EffortJointInterface</hardwareInterface>
      <mechanicalReduction>1</mechanicalReduction>
    </actuator>
  </transmission>
  <transmission name="Slider6_tran">
    <type>transmission_interface/SimpleTransmission</type>
    <joint name="Slider6">
      <hardwareInterface>hardware_interface/EffortJointInterface</hardwareInterface>
    </joint>
    <actuator name="Slider6_actr">
      <hardwareInterface>hardware_interface/EffortJointInterface</hardwareInterface>
      <mechanicalReduction>1</mechanicalReduction>
    </actuator>
  </transmission>
  <gazebo>
    <plugin filename="libgazebo_ros_control.so" name="control"/>
  </gazebo>
  <gazebo reference="base_link">
    <material>Gazebo/Silver</material>
    <mu1>0.2</mu1>
    <mu2>0.2</mu2>
    <selfCollide>true</selfCollide>
    <gravity>true</gravity>
  </gazebo>
  <gazebo reference="Joint1_1">
    <material>Gazebo/Silver</material>
    <mu1>0.2</mu1>
    <mu2>0.2</mu2>
    <selfCollide>true</selfCollide>
  </gazebo>
  <gazebo reference="Joint2_1">
    <material>Gazebo/Silver</material>
    <mu1>0.2</mu1>
    <mu2>0.2</mu2>
    <selfCollide>true</selfCollide>
  </gazebo>
  <gazebo reference="Joint3_1">
    <material>Gazebo/Silver</material>
    <mu1>0.2</mu1>
    <mu2>0.2</mu2>
    <selfCollide>true</selfCollide>
  </gazebo>
  <gazebo reference="Joint4_1">
    <material>Gazebo/Silver</material>
    <mu1>0.2</mu1>
    <mu2>0.2</mu2>
    <selfCollide>true</selfCollide>
  </gazebo>
  <gazebo reference="Right_jaw_1">
    <material>Gazebo/Silver</material>
    <mu1>0.2</mu1>
    <mu2>0.2</mu2>
    <selfCollide>true</selfCollide>
  </gazebo>
  <gazebo reference="Left_jaw_1">
    <material>Gazebo/Silver</material>
    <mu1>0.2</mu1>
    <mu2>0.2</mu2>
    <selfCollide>true</selfCollide>
  </gazebo>
  <link name="base_link">
    <inertial>
      <origin rpy="0 0 0" xyz="0.030646133274272267 -0.00025705252992554053 0.020795406083224673"/>
      <mass value="1.4664796275911582"/>
      <inertia ixx="0.001586" ixy="1e-06" ixz="2.8e-05" iyy="0.004086" iyz="-2.1e-05" izz="0.004908"/>
    </inertial>
    <visual>
      <origin rpy="0 0 0" xyz="0 0 0"/>
      <geometry>
        <mesh filename="package://URDF_description/meshes/base_link.stl" scale="0.001 0.001 0.001"/>
      </geometry>
      <material name="silver"/>
    </visual>
    <collision>
      <origin rpy="0 0 0" xyz="0 0 0"/>
      <geometry>
        <mesh filename="package://URDF_description/meshes/base_link.stl" scale="0.001 0.001 0.001"/>
      </geometry>
    </collision>
  </link>
  <link name="Joint1_1">
    <inertial>
      <origin rpy="0 0 0" xyz="0.0005329147611793454 0.0014563495351705054 0.015157418304501208"/>
      <mass value="0.49051731516542596"/>
      <inertia ixx="0.000431" ixy="0.0" ixz="1e-06" iyy="0.000277" iyz="-7e-06" izz="0.000535"/>
    </inertial>
    <visual>
      <origin rpy="0 0 0" xyz="0.000121 0.001909 -0.043"/>
      <geometry>
        <mesh filename="package://URDF_description/meshes/Joint1_1.stl" scale="0.001 0.001 0.001"/>
      </geometry>
      <material name="silver"/>
    </visual>
    <collision>
      <origin rpy="0 0 0" xyz="0.000121 0.001909 -0.043"/>
      <geometry>
        <mesh filename="package://URDF_description/meshes/Joint1_1.stl" scale="0.001 0.001 0.001"/>
      </geometry>
    </collision>
  </link>
  <link name="Joint2_1">
    <inertial>
      <origin rpy="0 0 0" xyz="0.048707572168144045 -0.021120125070860845 -0.00013257786523988846"/>
      <mass value="0.701502571183849"/>
      <inertia ixx="0.00058" ixy="-4.5e-05" ixz="2e-06" iyy="0.00086" iyz="-2e-06" izz="0.001212"/>
    </inertial>
    <visual>
      <origin rpy="0 0 0" xyz="0.00013 -0.021091 -0.0755"/>
      <geometry>
        <mesh filename="package://URDF_description/meshes/Joint2_1.stl" scale="0.001 0.001 0.001"/>
      </geometry>
      <material name="silver"/>
    </visual>
    <collision>
      <origin rpy="0 0 0" xyz="0.00013 -0.021091 -0.0755"/>
      <geometry>
        <mesh filename="package://URDF_description/meshes/Joint2_1.stl" scale="0.001 0.001 0.001"/>
      </geometry>
    </collision>
  </link>
  <link name="Joint3_1">
    <inertial>
      <origin rpy="0 0 0" xyz="-0.027417713845527297 -0.021508487339836967 0.027021192126078633"/>
      <mass value="0.5904481206007668"/>
      <inertia ixx="0.000475" ixy="-6e-06" ixz="0.000123" iyy="0.000798" iyz="-2e-05" izz="0.000842"/>
    </inertial>
    <visual>
      <origin rpy="0 0 0" xyz="-0.08987 -0.021101 -0.0755"/>
      <geometry>
        <mesh filename="package://URDF_description/meshes/Joint3_1.stl" scale="0.001 0.001 0.001"/>
      </geometry>
      <material name="silver"/>
    </visual>
    <collision>
      <origin rpy="0 0 0" xyz="-0.08987 -0.021101 -0.0755"/>
      <geometry>
        <mesh filename="package://URDF_description/meshes/Joint3_1.stl" scale="0.001 0.001 0.001"/>
      </geometry>
    </collision>
  </link>
  <link name="Joint4_1">
    <inertial>
      <origin rpy="0 0 0" xyz="-0.0028935402687894534 -0.023149716954682202 -8.315819780418954e-07"/>
      <mass value="0.23259176688485017"/>
      <inertia ixx="8.2e-05" ixy="-4e-06" ixz="0.0" iyy="3.5e-05" iyz="-0.0" izz="8.2e-05"/>
    </inertial>
    <visual>
      <origin rpy="0 0 0" xyz="-0.007167 -0.021111 -0.111"/>
      <geometry>
        <mesh filename="package://URDF_description/meshes/Joint4_1.stl" scale="0.001 0.001 0.001"/>
      </geometry>
      <material name="silver"/>
    </visual>
    <collision>
      <origin rpy="0 0 0" xyz="-0.007167 -0.021111 -0.111"/>
      <geometry>
        <mesh filename="package://URDF_description/meshes/Joint4_1.stl" scale="0.001 0.001 0.001"/>
      </geometry>
    </collision>
  </link>
  <link name="Right_jaw_1">
    <inertial>
      <origin rpy="0 0 0" xyz="-0.008029685775087147 -0.01623400794041338 0.0002096419702396629"/>
      <mass value="0.026847764745505966"/>
      <inertia ixx="3e-06" ixy="-0.0" ixz="-0.0" iyy="4e-06" iyz="-0.0" izz="1e-06"/>
    </inertial>
    <visual>
      <origin rpy="0 0 0" xyz="0.010333 -0.020611 -0.111"/>
      <geometry>
        <mesh filename="package://URDF_description/meshes/Right_jaw_1.stl" scale="0.001 0.001 0.001"/>
      </geometry>
      <material name="silver"/>
    </visual>
    <collision>
      <origin rpy="0 0 0" xyz="0.010333 -0.020611 -0.111"/>
      <geometry>
        <mesh filename="package://URDF_description/meshes/Right_jaw_1.stl" scale="0.001 0.001 0.001"/>
      </geometry>
    </collision>
  </link>
  <link name="Left_jaw_1">
    <inertial>
      <origin rpy="0 0 0" xyz="-0.008029717819042945 0.016233468870598598 -0.00020973773489249559"/>
      <mass value="0.02684775454507079"/>
      <inertia ixx="3e-06" ixy="0.0" ixz="0.0" iyy="4e-06" iyz="-0.0" izz="1e-06"/>
    </inertial>
    <visual>
      <origin rpy="0 0 0" xyz="0.010333 0.024389 -0.111"/>
      <geometry>
        <mesh filename="package://URDF_description/meshes/Left_jaw_1.stl" scale="0.001 0.001 0.001"/>
      </geometry>
      <material name="silver"/>
    </visual>
    <collision>
      <origin rpy="0 0 0" xyz="0.010333 0.024389 -0.111"/>
      <geometry>
        <mesh filename="package://URDF_description/meshes/Left_jaw_1.stl" scale="0.001 0.001 0.001"/>
      </geometry>
    </collision>
  </link>
  <joint name="Revolute1" type="revolute">
    <origin rpy="0 0 0" xyz="-0.000121 -0.001909 0.043"/>
    <parent link="base_link"/>
    <child link="Joint1_1"/>
    <axis xyz="0.0 0.0 1.0"/>
    <limit effort="100" lower="-1.570796" upper="1.570796" velocity="100"/>
  </joint>
  <joint name="Revolute2" type="revolute">
    <origin rpy="0 0 0" xyz="-9e-06 0.023 0.0325"/>
    <parent link="Joint1_1"/>
    <child link="Joint2_1"/>
    <axis xyz="0.0 -1.0 0.0"/>
    <limit effort="100" lower="0.0" upper="3.141593" velocity="100"/>
  </joint>
  <joint name="Revolute3" type="revolute">
    <origin rpy="0 0 0" xyz="0.09 1e-05 0.0"/>
    <parent link="Joint2_1"/>
    <child link="Joint3_1"/>
    <axis xyz="0.0 -1.0 0.0"/>
    <limit effort="100" lower="3.141593" upper="6.283185" velocity="100"/>
  </joint>
  <joint name="Revolute4" type="revolute">
    <origin rpy="0 0 0" xyz="-0.082703 1e-05 0.0355"/>
    <parent link="Joint3_1"/>
    <child link="Joint4_1"/>
    <axis xyz="-0.0 -1.0 0.0"/>
    <limit effort="100" lower="-1.570796" upper="1.570796" velocity="100"/>
  </joint>
  <joint name="Slider5" type="prismatic">
    <origin rpy="0 0 0" xyz="-0.0175 -0.0005 0.0"/>
    <parent link="Joint4_1"/>
    <child link="Right_jaw_1"/>
    <axis xyz="0.0 1.0 -0.0"/>
    <limit effort="100" lower="0.0" upper="0.006" velocity="100"/>
  </joint>
  <joint name="Slider6" type="prismatic">
    <origin rpy="0 0 0" xyz="-0.0175 -0.0455 0.0"/>
    <parent link="Joint4_1"/>
    <child link="Left_jaw_1"/>
    <axis xyz="-0.0 -1.0 0.0"/>
    <limit effort="100" lower="0.0" upper="0.006" velocity="100"/>
  </joint>
</robot>
