<?xml version="1.0" ?>
<!-- =================================================================================== -->
<!-- |    This document was autogenerated by xacro from URDF.xacro                     | -->
<!-- |    EDITING THIS FILE BY HAND IS NOT RECOMMENDED                                 | -->
<!-- =================================================================================== -->
<robot name="URDF">
  <material name="silver">
    <color rgba="0.700 0.700 0.700 1.000"/>
  </material>
  <transmission name="Revolute_1_tran">
    <type>transmission_interface/SimpleTransmission</type>
    <joint name="Revolute_1">
      <hardwareInterface>hardware_interface/EffortJointInterface</hardwareInterface>
    </joint>
    <actuator name="Revolute_1_actr">
      <hardwareInterface>hardware_interface/EffortJointInterface</hardwareInterface>
      <mechanicalReduction>1</mechanicalReduction>
    </actuator>
  </transmission>
  <transmission name="Revolute_2_tran">
    <type>transmission_interface/SimpleTransmission</type>
    <joint name="Revolute_2">
      <hardwareInterface>hardware_interface/EffortJointInterface</hardwareInterface>
    </joint>
    <actuator name="Revolute_2_actr">
      <hardwareInterface>hardware_interface/EffortJointInterface</hardwareInterface>
      <mechanicalReduction>1</mechanicalReduction>
    </actuator>
  </transmission>
  <transmission name="Revolute_3_tran">
    <type>transmission_interface/SimpleTransmission</type>
    <joint name="Revolute_3">
      <hardwareInterface>hardware_interface/EffortJointInterface</hardwareInterface>
    </joint>
    <actuator name="Revolute_3_actr">
      <hardwareInterface>hardware_interface/EffortJointInterface</hardwareInterface>
      <mechanicalReduction>1</mechanicalReduction>
    </actuator>
  </transmission>
  <transmission name="Revolute_4_tran">
    <type>transmission_interface/SimpleTransmission</type>
    <joint name="Revolute_4">
      <hardwareInterface>hardware_interface/EffortJointInterface</hardwareInterface>
    </joint>
    <actuator name="Revolute_4_actr">
      <hardwareInterface>hardware_interface/EffortJointInterface</hardwareInterface>
      <mechanicalReduction>1</mechanicalReduction>
    </actuator>
  </transmission>
  <transmission name="Slider_5_tran">
    <type>transmission_interface/SimpleTransmission</type>
    <joint name="Slider_5">
      <hardwareInterface>hardware_interface/EffortJointInterface</hardwareInterface>
    </joint>
    <actuator name="Slider_5_actr">
      <hardwareInterface>hardware_interface/EffortJointInterface</hardwareInterface>
      <mechanicalReduction>1</mechanicalReduction>
    </actuator>
  </transmission>
  <transmission name="Slider_6_tran">
    <type>transmission_interface/SimpleTransmission</type>
    <joint name="Slider_6">
      <hardwareInterface>hardware_interface/EffortJointInterface</hardwareInterface>
    </joint>
    <actuator name="Slider_6_actr">
      <hardwareInterface>hardware_interface/EffortJointInterface</hardwareInterface>
      <mechanicalReduction>1</mechanicalReduction>
    </actuator>
  </transmission>
  <gazebo>
    <plugin filename="libgazebo_ros_control.so" name="control"/>
  </gazebo>
  <gazebo reference="base_link">
    <material>Gazebo/Silver</material>
    <mu1>0.2</mu1>
    <mu2>0.2</mu2>
    <selfCollide>true</selfCollide>
    <gravity>true</gravity>
  </gazebo>
  <gazebo reference="JOINT1_v1_1">
    <material>Gazebo/Silver</material>
    <mu1>0.2</mu1>
    <mu2>0.2</mu2>
    <selfCollide>true</selfCollide>
  </gazebo>
  <gazebo reference="JOINT2_v1_1">
    <material>Gazebo/Silver</material>
    <mu1>0.2</mu1>
    <mu2>0.2</mu2>
    <selfCollide>true</selfCollide>
  </gazebo>
  <gazebo reference="JOINT3_v1_1">
    <material>Gazebo/Silver</material>
    <mu1>0.2</mu1>
    <mu2>0.2</mu2>
    <selfCollide>true</selfCollide>
  </gazebo>
  <gazebo reference="JOINT4_v1_1">
    <material>Gazebo/Silver</material>
    <mu1>0.2</mu1>
    <mu2>0.2</mu2>
    <selfCollide>true</selfCollide>
  </gazebo>
  <gazebo reference="left_jaw_v1_1">
    <material>Gazebo/Silver</material>
    <mu1>0.2</mu1>
    <mu2>0.2</mu2>
    <selfCollide>true</selfCollide>
  </gazebo>
  <gazebo reference="right_jaw_v1_1">
    <material>Gazebo/Silver</material>
    <mu1>0.2</mu1>
    <mu2>0.2</mu2>
    <selfCollide>true</selfCollide>
  </gazebo>
  <link name="base_link">
    <inertial>
      <origin rpy="0 0 0" xyz="0.015383407578683417 0.001784568400188029 0.027310424563411515"/>
      <mass value="0.9096816380238157"/>
      <inertia ixx="0.001044" ixy="-6.7e-05" ixz="-8.7e-05" iyy="0.001908" iyz="-1.7e-05" izz="0.002592"/>
    </inertial>
    <visual>
      <origin rpy="0 0 0" xyz="0 0 0"/>
      <geometry>
        <mesh filename="package://URDF_description/meshes/base_link.stl" scale="0.001 0.001 0.001"/>
      </geometry>
      <material name="silver"/>
    </visual>
    <collision>
      <origin rpy="0 0 0" xyz="0 0 0"/>
      <geometry>
        <mesh filename="package://URDF_description/meshes/base_link.stl" scale="0.001 0.001 0.001"/>
      </geometry>
    </collision>
  </link>
  <link name="JOINT1_v1_1">
    <inertial>
      <origin rpy="0 0 0" xyz="0.0006187257393876559 0.002218911748643823 0.013844723512104036"/>
      <mass value="0.43372533375582556"/>
      <inertia ixx="0.000362" ixy="1e-06" ixz="1e-06" iyy="0.000261" iyz="-9e-06" izz="0.000475"/>
    </inertial>
    <visual>
      <origin rpy="0 0 0" xyz="-0.0 -0.0 -0.043"/>
      <geometry>
        <mesh filename="package://URDF_description/meshes/JOINT1_v1_1.stl" scale="0.001 0.001 0.001"/>
      </geometry>
      <material name="silver"/>
    </visual>
    <collision>
      <origin rpy="0 0 0" xyz="-0.0 -0.0 -0.043"/>
      <geometry>
        <mesh filename="package://URDF_description/meshes/JOINT1_v1_1.stl" scale="0.001 0.001 0.001"/>
      </geometry>
    </collision>
  </link>
  <link name="JOINT2_v1_1">
    <inertial>
      <origin rpy="0 0 0" xyz="0.044247351794378734 -0.018025078758444557 -0.0003453175523793345"/>
      <mass value="0.5872350752757163"/>
      <inertia ixx="0.000404" ixy="-5.6e-05" ixz="4e-06" iyy="0.000702" iyz="-0.0" izz="0.000913"/>
    </inertial>
    <visual>
      <origin rpy="0 0 0" xyz="9e-06 -0.023 -0.0755"/>
      <geometry>
        <mesh filename="package://URDF_description/meshes/JOINT2_v1_1.stl" scale="0.001 0.001 0.001"/>
      </geometry>
      <material name="silver"/>
    </visual>
    <collision>
      <origin rpy="0 0 0" xyz="9e-06 -0.023 -0.0755"/>
      <geometry>
        <mesh filename="package://URDF_description/meshes/JOINT2_v1_1.stl" scale="0.001 0.001 0.001"/>
      </geometry>
    </collision>
  </link>
  <link name="JOINT3_v1_1">
    <inertial>
      <origin rpy="0 0 0" xyz="-0.022295142057999803 -0.024368276823764995 0.025631681377685928"/>
      <mass value="0.5028713990731921"/>
      <inertia ixx="0.000393" ixy="-3.1e-05" ixz="9.7e-05" iyy="0.000642" iyz="-6e-06" izz="0.000632"/>
    </inertial>
    <visual>
      <origin rpy="0 0 0" xyz="-0.089991 -0.02301 -0.0755"/>
      <geometry>
        <mesh filename="package://URDF_description/meshes/JOINT3_v1_1.stl" scale="0.001 0.001 0.001"/>
      </geometry>
      <material name="silver"/>
    </visual>
    <collision>
      <origin rpy="0 0 0" xyz="-0.089991 -0.02301 -0.0755"/>
      <geometry>
        <mesh filename="package://URDF_description/meshes/JOINT3_v1_1.stl" scale="0.001 0.001 0.001"/>
      </geometry>
    </collision>
  </link>
  <link name="JOINT4_v1_1">
    <inertial>
      <origin rpy="0 0 0" xyz="-0.0022534021040759205 -0.023791769129191773 -2.6291795823807362e-08"/>
      <mass value="0.20627022272536225"/>
      <inertia ixx="7e-05" ixy="-4e-06" ixz="0.0" iyy="3e-05" iyz="-0.0" izz="6.8e-05"/>
    </inertial>
    <visual>
      <origin rpy="0 0 0" xyz="-0.007288 -0.02302 -0.111"/>
      <geometry>
        <mesh filename="package://URDF_description/meshes/JOINT4_v1_1.stl" scale="0.001 0.001 0.001"/>
      </geometry>
      <material name="silver"/>
    </visual>
    <collision>
      <origin rpy="0 0 0" xyz="-0.007288 -0.02302 -0.111"/>
      <geometry>
        <mesh filename="package://URDF_description/meshes/JOINT4_v1_1.stl" scale="0.001 0.001 0.001"/>
      </geometry>
    </collision>
  </link>
  <link name="left_jaw_v1_1">
    <inertial>
      <origin rpy="0 0 0" xyz="-0.00806421962618316 0.014519522589371003 3.7969627442180354e-14"/>
      <mass value="0.03602585798484725"/>
      <inertia ixx="3e-06" ixy="0.0" ixz="0.0" iyy="5e-06" iyz="0.0" izz="2e-06"/>
    </inertial>
    <visual>
      <origin rpy="0 0 0" xyz="0.010212 0.02248 -0.111"/>
      <geometry>
        <mesh filename="package://URDF_description/meshes/left_jaw_v1_1.stl" scale="0.001 0.001 0.001"/>
      </geometry>
      <material name="silver"/>
    </visual>
    <collision>
      <origin rpy="0 0 0" xyz="0.010212 0.02248 -0.111"/>
      <geometry>
        <mesh filename="package://URDF_description/meshes/left_jaw_v1_1.stl" scale="0.001 0.001 0.001"/>
      </geometry>
    </collision>
  </link>
  <link name="right_jaw_v1_1">
    <inertial>
      <origin rpy="0 0 0" xyz="-0.008064219626183875 -0.014519522589366726 3.799738301779598e-14"/>
      <mass value="0.03602585798484718"/>
      <inertia ixx="3e-06" ixy="-0.0" ixz="-0.0" iyy="5e-06" iyz="0.0" izz="2e-06"/>
    </inertial>
    <visual>
      <origin rpy="0 0 0" xyz="0.010212 -0.02252 -0.111"/>
      <geometry>
        <mesh filename="package://URDF_description/meshes/right_jaw_v1_1.stl" scale="0.001 0.001 0.001"/>
      </geometry>
      <material name="silver"/>
    </visual>
    <collision>
      <origin rpy="0 0 0" xyz="0.010212 -0.02252 -0.111"/>
      <geometry>
        <mesh filename="package://URDF_description/meshes/right_jaw_v1_1.stl" scale="0.001 0.001 0.001"/>
      </geometry>
    </collision>
  </link>
  <joint name="Revolute_1" type="revolute">
    <origin rpy="0 0 0" xyz="0.0 0.0 0.043"/>
    <parent link="base_link"/>
    <child link="JOINT1_v1_1"/>
    <axis xyz="0.0 0.0 1.0"/>
    <limit effort="100" lower="-1.570796" upper="1.570796" velocity="100"/>
  </joint>
  <joint name="Revolute_2" type="revolute">
    <origin rpy="0 0 0" xyz="-9e-06 0.023 0.0325"/>
    <parent link="JOINT1_v1_1"/>
    <child link="JOINT2_v1_1"/>
    <axis xyz="0.0 1.0 0.0"/>
    <limit effort="100" lower="-3.141593" upper="0.0" velocity="100"/>
  </joint>
  <joint name="Revolute_3" type="revolute">
    <origin rpy="0 0 0" xyz="0.09 1e-05 0.0"/>
    <parent link="JOINT2_v1_1"/>
    <child link="JOINT3_v1_1"/>
    <axis xyz="-0.0 1.0 -0.0"/>
    <limit effort="100" lower="0.0" upper="3.141593" velocity="100"/>
  </joint>
  <joint name="Revolute_4" type="revolute">
    <origin rpy="0 0 0" xyz="-0.082703 1e-05 0.0355"/>
    <parent link="JOINT3_v1_1"/>
    <child link="JOINT4_v1_1"/>
    <axis xyz="-0.0 1.0 0.0"/>
    <limit effort="100" lower="-1.570796" upper="1.570796" velocity="100"/>
  </joint>
  <joint name="Slider_5" type="prismatic">
    <origin rpy="0 0 0" xyz="-0.0175 -0.0455 0.0"/>
    <parent link="JOINT4_v1_1"/>
    <child link="left_jaw_v1_1"/>
    <axis xyz="0.0 -1.0 0.0"/>
    <limit effort="100" lower="0.0" upper="0.005" velocity="100"/>
  </joint>
  <joint name="Slider_6" type="prismatic">
    <origin rpy="0 0 0" xyz="-0.0175 -0.0005 0.0"/>
    <parent link="JOINT4_v1_1"/>
    <child link="right_jaw_v1_1"/>
    <axis xyz="-0.0 1.0 -0.0"/>
    <limit effort="100" lower="0.0" upper="0.005" velocity="100"/>
  </joint>
</robot>

